Traceback (most recent call last):
  File "/home/aeroglu/irods-env/lib/python3.11/site-packages/irods/session.py", line 257, in _configure_account
    env_file = kwargs["irods_env_file"]
               ~~~~~~^^^^^^^^^^^^^^^^^^
KeyError: 'irods_env_file'

During handling of the above exception, another exception occurred:

Traceback (most recent call last):
  File "<stdin>", line 8, in <module>
  File "/home/aeroglu/irods-env/lib/python3.11/site-packages/irods/session.py", line 169, in __init__
    self.__configured = self.configure(**kwargs)
                        ^^^^^^^^^^^^^^^^^^^^^^^^
  File "/home/aeroglu/irods-env/lib/python3.11/site-packages/irods/session.py", line 325, in configure
    account = self._configure_account(**kwargs)
              ^^^^^^^^^^^^^^^^^^^^^^^^^^^^^^^^^
  File "/home/aeroglu/irods-env/lib/python3.11/site-packages/irods/session.py", line 268, in _configure_account
    return iRODSAccount(**kwargs)
           ^^^^^^^^^^^^^^^^^^^^^^
TypeError: iRODSAccount.__init__() missing 4 required positional arguments: 'irods_host', 'irods_port', 'irods_user_name', and 'irods_zone_name'
